Workbook

Sheet EXP_comp
A1: Ditta | B1: Ragione sociale (anagrafica) | C1: CodiceConto | D1: Descrizione conto | E1: M | F1: sM | G1: DareAvere1 | H1: 2023 | I1: DareAvere2 | J1: 2024 | K1: Perc1 | L1: DareAvere3 | M1: 2025 | N1: Perc2
A2: 112 | B2: F.LLI BERTI SRL | C2: 03/05/005 | D2: COSTI DI IMPIANTO | G2: D | H2: 2800 | I2: D | J2: 2800 | L2: D | M2: 2800
A3: 112 | B3: F.LLI BERTI SRL | C3: 03/05/000 | D3: COSTI DI IMPIANTO E AMPLIAMENTO | G3: D | H3: 2800 | I3: D | J3: 2800 | L3: D | M3: 2800
A4: 112 | B4: F.LLI BERTI SRL | C4: 03/00/000 | D4: IMMOBILIZZAZIONI IMMATERIALI | G4: D | H4: 2800 | I4: D | J4: 2800 | L4: D | M4: 2800
A5: 112 | B5: F.LLI BERTI SRL | C5: 06/05/020 | D5: COSTRUZIONI LEGGERE | G5: D | H5: 346.75 | I5: D | J5: 346.75 | L5: D | M5: 346.75
A6: 112 | B6: F.LLI BERTI SRL | C6: 06/05/000 | D6: TERRENI E FABBRICATI | G6: D | H6: 346.75 | I6: D | J6: 346.75 | L6: D | M6: 346.75
A7: 112 | B7: F.LLI BERTI SRL | C7: 06/10/005 | D7: IMPIANTI GENERICI | G7: D | H7: 16232.4 | I7: D | J7: 16232.4 | L7: D | M7: 16232.4
A8: 112 | B8: F.LLI BERTI SRL | C8: 06/10/015 | D8: MACCHINARI | G8: D | H8: 4050 | I8: D | J8: 15116.17 | K8: 73,207- | L8: D | M8: 15116.17
A9: 112 | B9: F.LLI BERTI SRL | C9: 06/10/000 | D9: IMPIANTI E MACCHINARIO | G9: D | H9: 20282.4 | I9: D | J9: 31348.57 | K9: 35,300- | L9: D | M9: 31348.57
A10: 112 | B10: F.LLI BERTI SRL | C10: 06/15/005 | D10: ATTREZZAT. IND.LI E COMM.LI | G10: D | H10: 5030.4 | I10: D | J10: 5030.4 | L10: D | M10: 5030.4
A11: 112 | B11: F.LLI BERTI SRL | C11: 06/15/010 | D11: ATTR.VARIE E MINUTE (<516,46 E.) | G11: D | H11: 790 | I11: D | J11: 790 | L11: D | M11: 790
A12: 112 | B12: F.LLI BERTI SRL | C12: 06/15/000 | D12: ATTREZZATURE IND.LI E COMM.LI | G12: D | H12: 5820.4 | I12: D | J12: 5820.4 | L12: D | M12: 5820.4
A13: 112 | B13: F.LLI BERTI SRL | C13: 06/25/015 | D13: AUTOCARRI/AUTOVETTURE | G13: D | H13: 146878.61 | I13: D | J13: 153947.72 | K13: 4,591- | L13: D | M13: 153947.72
A14: 112 | B14: F.LLI BERTI SRL | C14: 06/25/000 | D14: AUTOMEZZI (ALTRI BENI) | G14: D | H14: 146878.61 | I14: D | J14: 153947.72 | K14: 4,591- | L14: D | M14: 153947.72
A15: 112 | B15: F.LLI BERTI SRL | C15: 06/00/000 | D15: IMMOBILIZZAZIONI MATERIALI | G15: D | H15: 173328.16 | I15: D | J15: 191463.44 | K15: 9,471- | L15: D | M15: 191463.44
A16: 112 | B16: F.LLI BERTI SRL | C16: 09/15/501 | D16: QUOTE SOCIALI FIDIMPRESA MARCH | G16: D | H16: 701.76 | I16: D | J16: 701.76 | L16: D | M16: 701.76
A17: 112 | B17: F.LLI BERTI SRL | C17: 09/15/000 | D17: ALTRI TITOLI | G17: D | H17: 701.76 | I17: D | J17: 701.76 | L17: D | M17: 701.76
A18: 112 | B18: F.LLI BERTI SRL | C18: 09/00/000 | D18: IMMOBILIZZAZIONI FINANZIARIE | G18: D | H18: 701.76 | I18: D | J18: 701.76 | L18: D | M18: 701.76
A19: 112 | B19: F.LLI BERTI SRL | C19: 11/05/020 | D19: MATERIALI VARI | G19: D | H19: 645.81 | I19: D | J19: 3602.11 | K19: 82,071- | M19: 0 | N19: 100
A20: 112 | B20: F.LLI BERTI SRL | C20: 11/05/000 | D20: MATERIE PRIME, SUSS.E DI CONSUMO | G20: D | H20: 645.81 | I20: D | J20: 3602.11 | K20: 82,071- | M20: 0 | N20: 100
A21: 112 | B21: F.LLI BERTI SRL | C21: 11/15/005 | D21: LAV.IN CORSO SU ORD. (<12 MESI) | G21: D | H21: 116575 | I21: D | J21: 11275 | K21: 933,924 | L21: D | M21: 24450 | N21: -53.885
A22: 112 | B22: F.LLI BERTI SRL | C22: 11/15/000 | D22: LAVORI IN CORSO SU ORDINAZIONE | G22: D | H22: 116575 | I22: D | J22: 11275 | K22: 933,924 | L22: D | M22: 24450 | N22: -53.885
A23: 112 | B23: F.LLI BERTI SRL | C23: 11/00/000 | D23: RIMANENZE | G23: D | H23: 117220.81 | I23: D | J23: 14877.11 | K23: 687,927 | L23: D | M23: 24450 | N23: -39.152
A24: 112 | B24: F.LLI BERTI SRL | C24: 14/00000 | D24: CREDITI V/CLIENTI | G24: D | H24: 43862.5 | I24: D | J24: 55359.05 | K24: 20,767- | L24: D | M24: 269974.41 | N24: -79.494
A25: 112 | B25: F.LLI BERTI SRL | C25: 15/05/501 | D25: FATTURE DA EMETTERE 2014 | G25: D | H25: 45588.94 | I25: D | J25: 45588.94 | L25: D | M25: 45588.94
A26: 112 | B26: F.LLI BERTI SRL | C26: 15/05/519 | D26: RIBA SBF - BPER BANCA | G26: D | H26: 50973 | I26: D | J26: 54731.22 | K26: 6,866- | L26: D | M26: 58050.13 | N26: -5.717
A27: 112 | B27: F.LLI BERTI SRL | C27: 15/05/000 | D27: ALTRI CREDITI V/CLIENTI | G27: D | H27: 96561.94 | I27: D | J27: 100320.16 | K27: 3,746- | L27: D | M27: 103639.07 | N27: -3.202
A28: 112 | B28: F.LLI BERTI SRL | C28: 15/00/000 | D28: ALTRI CREDITI V/CLIENTI | G28: D | H28: 96561.94 | I28: D | J28: 100320.16 | K28: 3,746- | L28: D | M28: 103639.07 | N28: -3.202
A29: 112 | B29: F.LLI BERTI SRL | C29: 18/20/068 | D29: ERARIO C/CR.IMP.INVES.BENI STRUM | G29: D | H29: 31821.76 | I29: D | J29: 23680.13 | K29: 34,381 | L29: D | M29: 23680.13
A30: 112 | B30: F.LLI BERTI SRL | C30: 18/20/527 | D30: RIMB.IRPEF DA 730 | G30: D | H30: 0 | J30: 0 | L30: D | M30: 730.55 | N30: -100
A31: 112 | B31: F.LLI BERTI SRL | C31: 18/20/534 | D31: ERARIO C/ACCONTI IRAP | G31: D | H31: 10126 | I31: D | J31: 8739 | K31: 15,871 | L31: D | M31: 10047 | N31: -13.018
A32: 112 | B32: F.LLI BERTI SRL | C32: 18/20/540 | D32: ERARIO C/RIT SUB 1039 A | G32: D | H32: 13585.71 | I32: D | J32: 25784.66 | K32: 47,310- | L32: D | M32: 14167.7 | N32: 81.996
A33: 112 | B33: F.LLI BERTI SRL | C33: 18/20/541 | D33: ERARIO C/RIT.SU INT ATT. A | G33: D | H33: 65.93 | I33: D | J33: 138.86 | K33: 52,520- | M33: 0 | N33: 100
A34: 112 | B34: F.LLI BERTI SRL | C34: 18/20/554 | D34: ERARIO C/RITENUTE SUBITE CREDITO | G34: D | H34: 497.64 | I34: D | J34: 24 | K34: ***,000 | M34: 0 | N34: 100
A35: 112 | B35: F.LLI BERTI SRL | C35: 18/20/561 | D35: CRED.IMPOSTA ART.121 DL34/20 BON | G35: D | H35: 11517.9 | I35: D | J35: 11212.2 | K35: 2,726 | M35: 0 | N35: 100
A36: 112 | B36: F.LLI BERTI SRL | C36: 18/20/564 | D36: CRED.IMPOSTA ART.121 DL34/20 BON | G36: D | H36: 35165.1 | I36: D | J36: 23952.9 | K36: 46,809 | L36: D | M36: 23952.9
A37: 112 | B37: F.LLI BERTI SRL | C37: 18/20/000 | D37: CREDITI TRIBUTARI | G37: D | H37: 102780.04 | I37: D | J37: 93531.75 | K37: 9,887 | L37: D | M37: 72578.28 | N37: 28.87
A38: 112 | B38: F.LLI BERTI SRL | C38: 18/25/030 | D38: INAIL C/CONGUAGLIO | G38: D | H38: 447.84 | J38: 0 | K38: 100,000 | M38: 0
A39: 112 | B39: F.LLI BERTI SRL | C39: 18/25/000 | D39: CREDITI V/ISTITUTI PREVIDENZIALI | G39: D | H39: 447.84 | J39: 0 | K39: 100,000 | M39: 0
A40: 112 | B40: F.LLI BERTI SRL | C40: 18/30/005 | D40: SOCI C/PRELEVAMENTI | G40: D | H40: 0 | J40: 0 | L40: D | M40: 32.5 | N40: -100
...

Sheet Tab_RIEP
A1: Cliccare col testo dx su una qualsiasi casella nella tabella e fare AGGIORNA per aggiornare alle ultime modifiche
A2: Cliccare sull'icona "Filtro" a dx di "CONTI", selezionare in alto Campo "M" e riselezionare "Tutto", selezionare "sM" e riselezionare "Tutto"
A3: CONTI | B3: Somma di 2023 | C3: Somma di 2024 | D3: Somma di 2025
A4: CFix | B4: 181715 | C4: 204601.29 | D4: 185621.79
A5: CSV | B5: 35174.54 | C5: 55153.45 | D5: 33885.63
A6: CONSULENZA FISCALE DA IMPRESE | B6: 6868 | C6: 7147.55 | D6: 5756.36
A7: LIC. D'USO SOFTWARE DI ESERCIZIO | B7: 212.85 | C7: 278.76 | D7: 324
A8: SPESE ACCESSORIE SU ACQUISTI | B8: 150.63 | C8: 203.98 | D8: 211.39
A9: SPESE VARIE AMMINISTRATIVE | B9: 72.24 | C9: 2 | D9: 110.7
A10: ALTRI SERVIZI DEDUCIBILI | B10: 484 | C10: 887 | D10: 920.11
A11: PRODOTTI SANIF.E DISP.PROT.INDIV | B11: 108.55 | C11: 0 | D11: 0
A12: CANCELLERIA | B12: 0 | C12: 0 | D12: 91.97
A13: CARBURANTI E LUBRIFICANTI | B13: 6847.36 | C13: 6739.05 | D13: 5109.22
A14: INDUMENTI DI LAVORO | B14: 316.45 | C14: 290.17 | D14: 503.32
A15: MANUT.E RIPARAZ.BENI PROPRI 5% | B15: 4334.99 | C15: 2810.61 | D15: 7804.13
... A98: IRAP DELL'ESERCIZIO | B98: 8727.87 | C98: 10041.03 | D98: 0

Sheet PROSP
D2: =EXP_comp!B2 -> F.LLI BERTI SRL
D3: P.IVA 01049630419
D4: SEMPLIFICATA
D5: CPB : NO XXXX€ | E5: =Tab_RIEP!B3 -> Somma di 2023 | G5: =Tab_RIEP!C3 -> Somma di 2024 | I5: =Tab_RIEP!D3 -> Somma di 2025 | M5: Inserire il num di mesi aggiornati ---> | N5: 1
B6: M | C6: sM | E6: 2023 | G6: 2024 | I6: 2025 | K6: MEDIA | M6: BUDGET 2026 | N6: Proiez 2026 CONSUNTIVO | O6: 46053 | P6: 46081 | Q6: 46112 | R6: 46142 | S6: 46173 | T6: 46203 | U6: 46234 | V6: 46265 | W6: 46295 | X6: 46326 | Y6: 46356 | Z6: 46387
D7: RICAVI
B8: Ric | C8: RCV | D8: RICAVI | E8: =IFERROR(GETPIVOTDATA(""&E$5&"",Tab_RIEP!$A$3,"M",$B8,"sM",$C8),0) -> 384816.31 | G8: =IFERROR(GETPIVOTDATA(""&G$5&"",Tab_RIEP!$A$3,"M",$B8,"sM",$C8),0) -> 643614.44 | I8: =IFERROR(GETPIVOTDATA(""&I$5&"",Tab_RIEP!$A$3,"M",$B8,"sM",$C8),0) -> 438078.74 | M8: =ROUND(I8,-3) -> 438000 | N8: =SUM(O8:Z8)/$N$5*12 -> 322536 | O8: 26878
D10: FATTURATO | E10: =E8 -> 384816.31 | F10: 1 | G10: =G8 -> 643614.44 | H10: 1 | I10: =I8 -> 438078.74 | J10: 1 | K10: =AVERAGE(F10,H10,J10) -> 1 | M10: =M8 -> 438000 | N10: =N8 -> 322536 | O10: =O8 -> 26878 | P10: =P8 -> 0 | Q10: =Q8 -> 0 | R10: =R8 -> 0 | S10: =S8 -> 0 | T10: =T8 -> 0 | ... Z10: =Z8 -> 0
B14: Cvar | C14: CAV | D14: COSTI P/MAT.PRI,SUSS.,CON.E MER. | E14: =IFERROR(GETPIVOTDATA(""&E$5&"",Tab_RIEP!$A$3,"M",$B14,"sM",$C14),0) -> 155359.3 | F14: =E14/$E$10 -> 0.40372327 | G14: =IFERROR(GETPIVOTDATA(""&G$5&"",Tab_RIEP!$A$3,"M",$B14,"sM",$C14),0) -> 173899.05 | H14: =G14/G$10 -> 0.27019134 | I14: =IFERROR(GETPIVOTDATA(""&I$5&"",Tab_RIEP!$A$3,"M",$B14,"sM",$C14),0) -> 152647.98 | J14: =I14/I$10 -> 0.34844873 | K14: =AVERAGE(F14,H14,J14) -> 0.34078778 | M14: =ROUND(I14,-2) -> 152600 | N14: =SUM(O14:Z14)/$N$5*12 -> 110400 | O14: =ROUND(O$10*$K14,-2) -> 9200 | P14: =ROUND(P$10*$K14,-2) -> 0 | Q14: =ROUND(Q$10*$K14,-2) -> 0 | R14: =ROUND(R$10*$K14,-2) -> 0 | S14: =ROUND(S$10*$K14,-2) -> 0 | T14: =ROUND(T$10*$K14,-2) -> 0 | U14: =ROUND(U$10*$K14,-2) -> 0 | V14: =ROUND(V$10*$K14,-2) -> 0 | ... Z14: =ROUND(Z$10*$K14,-2) -> 0
D16: TOTALE COSTI ACQUISTO | E16: =SUM(E14:E15) -> 155359.3 | F16: =E16/E$10 -> 0.40372327 | G16: =SUM(G14:G15) -> 173899.05 | H16: =G16/G$10 -> 0.27019134 | I16: =SUM(I14:I15) -> 152647.98 | J16: =I16/I$10 -> 0.34844873 | K16: =AVERAGE(F16,H16,J16) -> 0.34078778 | M16: =SUM(M14:M14) -> 152600 | N16: =SUM(N14:N14) -> 110400 | O16: =SUM(O14:O14) -> 9200 | P16: =SUM(P14:P14) -> 0 | Q16: =SUM(Q14:Q14) -> 0 | R16: =SUM(R14:R14) -> 0 | S16: =SUM(S14:S14) -> 0 | T16: =SUM(T14:T14) -> 0 | ... Z16: =SUM(Z14:Z14) -> 0
B18: Ric | C18: Rim_I | D18: RIMANENZE INIZIALI | E18: =IFERROR(GETPIVOTDATA(""&E$5&"",Tab_RIEP!$A$3,"M",$B18,"sM",$C18),0) -> 22305.77 | F18: =E18/$E$10 -> 0.057964721 | G18: =IFERROR(GETPIVOTDATA(""&G$5&"",Tab_RIEP!$A$3,"M",$B18,"sM",$C18),0) -> 117220.81 | H18: =G18/$G$10 -> 0.18212893 | I18: =IFERROR(GETPIVOTDATA(""&I$5&"",Tab_RIEP!$A$3,"M",$B18,"sM",$C18),0) -> 18479.22 | J18: =I18/$I$10 -> 0.042182417 | K18: =AVERAGE(F18,H18,J18) -> 0.094092023 | M18: =ROUND(I18,-2) -> 18500 | N18: =SUM(O18:Z18)/$N$5*12 -> 30000 | O18: =ROUND(O$10*$K18,-2) -> 2500 | P18: =ROUND(P$10*$K18,-2) -> 0 | Q18: =ROUND(Q$10*$K18,-2) -> 0 | R18: =ROUND(R$10*$K18,-2) -> 0 | S18: =ROUND(S$10*$K18,-2) -> 0 | T18: =ROUND(T$10*$K18,-2) -> 0 | U18: =ROUND(U$10*$K18,-2) -> 0 | V18: =ROUND(V$10*$K18,-2) -> 0 | ... Z18: =ROUND(Z$10*$K18,-2) -> 0
B19: Ric | C19: Rim_F | D19: RIMANENZE FINALI | E19: =IFERROR(GETPIVOTDATA(""&E$5&"",Tab_RIEP!$A$3,"M",$B19,"sM",$C19),0) -> 117220.81 | F19: =E19/$E$10 -> 0.30461497 | G19: =IFERROR(GETPIVOTDATA(""&G$5&"",Tab_RIEP!$A$3,"M",$B19,"sM",$C19),0) -> 14877.11 | H19: =G19/$G$10 -> 0.023114941 | I19: =IFERROR(GETPIVOTDATA(""&I$5&"",Tab_RIEP!$A$3,"M",$B19,"sM",$C19),0) -> 24450 | J19: =I19/$I$10 -> 0.055811884 | K19: =AVERAGE(F19,H19,J19) -> 0.12784727 | M19: =ROUND(I19,-2) -> 24500 | N19: =SUM(O19:Z19)/$N$5*12 -> 40800 | O19: =ROUND(O$10*$K19,-2) -> 3400 | P19: =ROUND(P$10*$K19,-2) -> 0 | Q19: =ROUND(Q$10*$K19,-2) -> 0 | R19: =ROUND(R$10*$K19,-2) -> 0 | S19: =ROUND(S$10*$K19,-2) -> 0 | T19: =ROUND(T$10*$K19,-2) -> 0 | U19: =ROUND(U$10*$K19,-2) -> 0 | V19: =ROUND(V$10*$K19,-2) -> 0 | ... Z19: =ROUND(Z$10*$K19,-2) -> 0
D20: SALDO RIMANENZE | E20: =E18-E19 -> -94915.04 | F20: =E20/$E$10 -> -0.24665025 | G20: =G18-G19 -> 102343.7 | H20: =G20/G$10 -> 0.15901399 | I20: =I18-I19 -> -5970.78 | J20: =I20/I$10 -> -0.013629468 | K20: =K18-K19 -> -0.033755243 | M20: =M18-M19 -> -6000 | N20: =N18-N19 -> -10800 | O20: =O18-O19 -> -900 | P20: =P18-P19 -> 0 | Q20: =Q18-Q19 -> 0 | R20: =R18-R19 -> 0 | S20: =S18-S19 -> 0 | T20: =T18-T19 -> 0 | ... Z20: =Z18-Z19 -> 0
D22: COSTO DEL VENDUTO | E22: =E16+E20 -> 60444.26 | F22: =E22/E$10 -> 0.15707302 | G22: =G16+G20 -> 276242.75 | H22: =G22/G$10 -> 0.42920533 | I22: =I16+I20 -> 146677.2 | J22: =I22/I$10 -> 0.33481926 | K22: =AVERAGE(F22,H22,J22) -> 0.30703254 | M22: =M16+M20 -> 146600 | N22: =N16+N20 -> 99600 | O22: =O16+O20 -> 8300 | P22: =P16+P20 -> 0 | Q22: =Q16+Q20 -> 0 | R22: =R16+R20 -> 0 | S22: =S16+S20 -> 0 | T22: =T16+T20 -> 0 | ... Z22: =Z16+Z20 -> 0
D26: TOTALE COSTI VARIABILI | E26: =SUM(E25:E25)+E22 -> 60444.26 | F26: =E26/$E$10 -> 0.15707302 | G26: =SUM(G25:G25)+G22 -> 276242.75 | H26: =G26/G$10 -> 0.42920533 | I26: =SUM(I25:I25)+I22 -> 146677.2 | J26: =I26/I$10 -> 0.33481926 | K26: =AVERAGE(F26,H26,J26) -> 0.30703254 | M26: =SUM(M25:M25)+M22 -> 146600 | N26: =SUM(N25:N25)+N22 -> 99600 | O26: =SUM(O25:O25)+O22 -> 8300 | P26: =SUM(P25:P25)+P22 -> 0 | Q26: =SUM(Q25:Q25)+Q22 -> 0 | R26: =SUM(R25:R25)+R22 -> 0 | S26: =SUM(S25:S25)+S22 -> 0 | T26: =SUM(T25:T25)+T22 -> 0 | ... Z26: =SUM(Z25:Z25)+Z22 -> 0
D28: MARGINE DI CONTRIBUZIONE | E28: =E10-E26 -> 324372.05 | F28: =E28/$E$10 -> 0.84292698 | G28: =G10-G26 -> 367371.69 | H28: =G28/G$10 -> 0.57079467 | I28: =I10-I26 -> 291401.54 | J28: =I28/I$10 -> 0.66518074 | K28: =AVERAGE(F28,H28,J28) -> 0.69296746 | M28: =M10-M26 -> 291400 | N28: =N10-N26 -> 222936 | O28: =O10-O26 -> 18578 | P28: =P10-P26 -> 0 | Q28: =Q10-Q26 -> 0 | R28: =R10-R26 -> 0 | S28: =S10-S26 -> 0 | T28: =T10-T26 -> 0 | ... Z28: =Z10-Z26 -> 0
B30: Cfix | C30: CSV | D30: COSTI PER SERVIZI | E30: =IFERROR(GETPIVOTDATA(""&E$5&"",Tab_RIEP!$A$3,"M",$B30,"sM",$C30),0) -> 35174.54 | F30: =E30/$E$10 -> 0.091406053 | G30: =IFERROR(GETPIVOTDATA(""&G$5&"",Tab_RIEP!$A$3,"M",$B30,"sM",$C30),0) -> 55153.45 | H30: =G30/G$10 -> 0.085693307 | I30: =IFERROR(GETPIVOTDATA(""&I$5&"",Tab_RIEP!$A$3,"M",$B30,"sM",$C30),0) -> 33885.63 | J30: =I30/I$10 -> 0.077350547 | K30: =AVERAGE(F30,H30,J30) -> 0.084816636 | M30: =ROUND(I30,-2) -> 33900 | N30: =SUM(O30:Z30)/$N$5*12 -> 33600 | O30: =IF(O$10>0,ROUND($M30/12,-2),0) -> 2800 | P30: =IF(P$10>0,ROUND($M30/12,-2),0) -> 0 | Q30: =IF(AND(P$10>0,Q$10>0),ROUND($M30/12,-2),IF(Q$10>0,ROUND($M30/4,-2),0)) -> 0 | R30: =IF(R$10>0,ROUND($M30/12,-2),0) -> 0 | S30: =IF(S$10>0,ROUND($M30/12,-2),0) -> 0 | T30: =IF(AND(S$10>0,T$10>0),ROUND($M30/12,-2),IF(T$10>0,ROUND($M30/4,-2),0)) -> 0 | U30: =IF(U$10>0,ROUND($M30/12,-2),0) -> 0 | V30: =IF(V$10>0,ROUND($M30/12,-2),0) -> 0 | W30: =IF(AND(V$10>0,W$10>0),ROUND($M30/12,-2),IF(W$10>0,ROUND($M30/4,-2),0)) -> 0 | X30: =IF(X$10>0,ROUND($M30/12,-2),0) -> 0 | Y30: =IF(Y$10>0,ROUND($M30/12,-2),0) -> 0 | Z30: =IF(AND(Y$10>0,Z$10>0),ROUND($M30/12,-2),IF(Z$10>0,ROUND($M30/4,-2),0)) -> 0
B31: Cfix | C31: CGT | D31: COSTI P/GODIMENTO BENI DI TERZI | E31: =IFERROR(GETPIVOTDATA(""&E$5&"",Tab_RIEP!$A$3,"M",$B31,"sM",$C31),0) -> 47708.5 | F31: =E31/$E$10 -> 0.12397733 | G31: =IFERROR(GETPIVOTDATA(""&G$5&"",Tab_RIEP!$A$3,"M",$B31,"sM",$C31),0) -> 40199.51 | H31: =G31/G$10 -> 0.062458993 | I31: =IFERROR(GETPIVOTDATA(""&I$5&"",Tab_RIEP!$A$3,"M",$B31,"sM",$C31),0) -> 40933.29 | J31: =I31/I$10 -> 0.093438202 | K31: =AVERAGE(F31,H31,J31) -> 0.09329151 | M31: =ROUND(I31,-2) -> 40900 | N31: =SUM(O31:Z31)/$N$5*12 -> 40800 | O31: =IF(O$10>0,ROUND($M31/12,-2),0) -> 3400 | P31: =IF(P$10>0,ROUND($M31/12,-2),0) -> 0 | Q31: =IF(AND(P$10>0,Q$10>0),ROUND($M31/12,-2),IF(Q$10>0,ROUND($M31/4,-2),0)) -> 0 | R31: =IF(R$10>0,ROUND($M31/12,-2),0) -> 0 | S31: =IF(S$10>0,ROUND($M31/12,-2),0) -> 0 | T31: =IF(AND(S$10>0,T$10>0),ROUND($M31/12,-2),IF(T$10>0,ROUND($M31/4,-2),0)) -> 0 | U31: =IF(U$10>0,ROUND($M31/12,-2),0) -> 0 | V31: =IF(V$10>0,ROUND($M31/12,-2),0) -> 0 | W31: =IF(AND(V$10>0,W$10>0),ROUND($M31/12,-2),IF(W$10>0,ROUND($M31/4,-2),0)) -> 0 | X31: =IF(X$10>0,ROUND($M31/12,-2),0) -> 0 | Y31: =IF(Y$10>0,ROUND($M31/12,-2),0) -> 0 | Z31: =IF(AND(Y$10>0,Z$10>0),ROUND($M31/12,-2),IF(Z$10>0,ROUND($M31/4,-2),0)) -> 0
B32: Cfix | C32: CPE | D32: COSTI PER IL PERSONALE | E32: =IFERROR(GETPIVOTDATA(""&E$5&"",Tab_RIEP!$A$3,"M",$B32,"sM",$C32),0) -> 47368 | F32: =E32/$E$10 -> 0.1230925 | G32: =IFERROR(GETPIVOTDATA(""&G$5&"",Tab_RIEP!$A$3,"M",$B32,"sM",$C32),0) -> 50980.59 | H32: =G32/G$10 -> 0.079209829 | I32: =IFERROR(GETPIVOTDATA(""&I$5&"",Tab_RIEP!$A$3,"M",$B32,"sM",$C32),0) -> 43946.26 | J32: =I32/I$10 -> 0.10031589 | K32: =AVERAGE(F32,H32,J32) -> 0.10087274 | M32: =ROUND(I32,-2) -> 43900 | N32: =SUM(O32:Z32)/$N$5*12 -> 44400 | O32: =IF(O$10>0,ROUND($M32/12,-2),0) -> 3700 | P32: =IF(P$10>0,ROUND($M32/12,-2),0) -> 0 | Q32: =IF(AND(P$10>0,Q$10>0),ROUND($M32/12,-2),IF(Q$10>0,ROUND($M32/4,-2),0)) -> 0 | R32: =IF(R$10>0,ROUND($M32/12,-2),0) -> 0 | S32: =IF(S$10>0,ROUND($M32/12,-2),0) -> 0 | T32: =IF(AND(S$10>0,T$10>0),ROUND($M32/12,-2),IF(T$10>0,ROUND($M32/4,-2),0)) -> 0 | U32: =IF(U$10>0,ROUND($M32/12,-2),0) -> 0 | V32: =IF(V$10>0,ROUND($M32/12,-2),0) -> 0 | W32: =IF(AND(V$10>0,W$10>0),ROUND($M32/12,-2),IF(W$10>0,ROUND($M32/4,-2),0)) -> 0 | X32: =IF(X$10>0,ROUND($M32/12,-2),0) -> 0 | Y32: =IF(Y$10>0,ROUND($M32/12,-2),0) -> 0 | Z32: =IF(AND(Y$10>0,Z$10>0),ROUND($M32/12,-2),IF(Z$10>0,ROUND($M32/4,-2),0)) -> 0
B33: Cfix | C33: AMM | D33: AMMORTAMENTI | E33: =IFERROR(GETPIVOTDATA(""&E$5&"",Tab_RIEP!$A$3,"M",$B33,"sM",$C33),0) -> 15395.95 | F33: =E33/$E$10 -> 0.040008569 | G33: =IFERROR(GETPIVOTDATA(""&G$5&"",Tab_RIEP!$A$3,"M",$B33,"sM",$C33),0) -> 29506.2 | H33: =G33/G$10 -> 0.045844528 | I33: =IFERROR(GETPIVOTDATA(""&I$5&"",Tab_RIEP!$A$3,"M",$B33,"sM",$C33),0) -> 32821.1 | J33: =I33/I$10 -> 0.07492055 | K33: =AVERAGE(F33,H33,J33) -> 0.053591216 | M33: =ROUND(I33,-2) -> 32800 | N33: =SUM(O33:Z33)/$N$5*12 -> 32400 | O33: =IF(O$10>0,ROUND($M33/12,-2),0) -> 2700 | P33: =IF(P$10>0,ROUND($M33/12,-2),0) -> 0 | Q33: =IF(AND(P$10>0,Q$10>0),ROUND($M33/12,-2),IF(Q$10>0,ROUND($M33/4,-2),0)) -> 0 | R33: =IF(R$10>0,ROUND($M33/12,-2),0) -> 0 | S33: =IF(S$10>0,ROUND($M33/12,-2),0) -> 0 | T33: =IF(AND(S$10>0,T$10>0),ROUND($M33/12,-2),IF(T$10>0,ROUND($M33/4,-2),0)) -> 0 | U33: =IF(U$10>0,ROUND($M33/12,-2),0) -> 0 | V33: =IF(V$10>0,ROUND($M33/12,-2),0) -> 0 | W33: =IF(AND(V$10>0,W$10>0),ROUND($M33/12,-2),IF(W$10>0,ROUND($M33/4,-2),0)) -> 0 | X33: =IF(X$10>0,ROUND($M33/12,-2),0) -> 0 | Y33: =IF(Y$10>0,ROUND($M33/12,-2),0) -> 0 | Z33: =IF(AND(Y$10>0,Z$10>0),ROUND($M33/12,-2),IF(Z$10>0,ROUND($M33/4,-2),0)) -> 0
B34: Cfix | C34: ODG | D34: ONERI DIVERSI DI GESTIONE | E34: =IFERROR(GETPIVOTDATA(""&E$5&"",Tab_RIEP!$A$3,"M",$B34,"sM",$C34),0) -> 28745.77 | F34: =E34/$E$10 -> 0.074699978 | G34: =IFERROR(GETPIVOTDATA(""&G$5&"",Tab_RIEP!$A$3,"M",$B34,"sM",$C34),0) -> 19935.31 | H34: =G34/G$10 -> 0.030973994 | I34: =IFERROR(GETPIVOTDATA(""&I$5&"",Tab_RIEP!$A$3,"M",$B34,"sM",$C34),0) -> 29303.83 | J34: =I34/I$10 -> 0.066891696 | K34: =AVERAGE(F34,H34,J34) -> 0.05752189 | M34: =ROUND(I34,-2) -> 29300 | N34: =SUM(O34:Z34)/$N$5*12 -> 28800 | O34: =IF(O$10>0,ROUND($M34/12,-2),0) -> 2400 | P34: =IF(P$10>0,ROUND($M34/12,-2),0) -> 0 | Q34: =IF(AND(P$10>0,Q$10>0),ROUND($M34/12,-2),IF(Q$10>0,ROUND($M34/4,-2),0)) -> 0 | R34: =IF(R$10>0,ROUND($M34/12,-2),0) -> 0 | S34: =IF(S$10>0,ROUND($M34/12,-2),0) -> 0 | T34: =IF(AND(S$10>0,T$10>0),ROUND($M34/12,-2),IF(T$10>0,ROUND($M34/4,-2),0)) -> 0 | U34: =IF(U$10>0,ROUND($M34/12,-2),0) -> 0 | V34: =IF(V$10>0,ROUND($M34/12,-2),0) -> 0 | W34: =IF(AND(V$10>0,W$10>0),ROUND($M34/12,-2),IF(W$10>0,ROUND($M34/4,-2),0)) -> 0 | X34: =IF(X$10>0,ROUND($M34/12,-2),0) -> 0 | Y34: =IF(Y$10>0,ROUND($M34/12,-2),0) -> 0 | Z34: =IF(AND(Y$10>0,Z$10>0),ROUND($M34/12,-2),IF(Z$10>0,ROUND($M34/4,-2),0)) -> 0
B35: Cfix | C35: INT | D35: INT. PASS.E ALTRI ONERI FINANZ. | E35: =IFERROR(GETPIVOTDATA(""&E$5&"",Tab_RIEP!$A$3,"M",$B35,"sM",$C35),0) -> 7322.24 | F35: =E35/$E$10 -> 0.019027884 | G35: =IFERROR(GETPIVOTDATA(""&G$5&"",Tab_RIEP!$A$3,"M",$B35,"sM",$C35),0) -> 8826.23 | H35: =G35/$G$10 -> 0.013713536 | I35: =IFERROR(GETPIVOTDATA(""&I$5&"",Tab_RIEP!$A$3,"M",$B35,"sM",$C35),0) -> 4731.68 | J35: =I35/$I$10 -> 0.010800981 | K35: =AVERAGE(F35,H35,J35) -> 0.014514134 | M35: =ROUND(I35,-2) -> 4700 | N35: =SUM(O35:Z35)/$N$5*12 -> 4800 | O35: =IF(O$10>0,ROUND($M35/12,-2),0) -> 400 | P35: =IF(P$10>0,ROUND($M35/12,-2),0) -> 0 | Q35: =IF(AND(P$10>0,Q$10>0),ROUND($M35/12,-2),IF(Q$10>0,ROUND($M35/4,-2),0)) -> 0 | R35: =IF(R$10>0,ROUND($M35/12,-2),0) -> 0 | S35: =IF(S$10>0,ROUND($M35/12,-2),0) -> 0 | T35: =IF(AND(S$10>0,T$10>0),ROUND($M35/12,-2),IF(T$10>0,ROUND($M35/4,-2),0)) -> 0 | U35: =IF(U$10>0,ROUND($M35/12,-2),0) -> 0 | V35: =IF(V$10>0,ROUND($M35/12,-2),0) -> 0 | W35: =IF(AND(V$10>0,W$10>0),ROUND($M35/12,-2),IF(W$10>0,ROUND($M35/4,-2),0)) -> 0 | X35: =IF(X$10>0,ROUND($M35/12,-2),0) -> 0 | Y35: =IF(Y$10>0,ROUND($M35/12,-2),0) -> 0 | Z35: =IF(AND(Y$10>0,Z$10>0),ROUND($M35/12,-2),IF(Z$10>0,ROUND($M35/4,-2),0)) -> 0
D36: COSTI FISSI DI GESTIONE | E36: =SUM(E30:E35) -> 181715 | F36: =E36/$E$10 -> 0.47221231 | G36: =SUM(G30:G35) -> 204601.29 | H36: =G36/G$10 -> 0.31789419 | I36: =SUM(I30:I35) -> 185621.79 | J36: =I36/I$10 -> 0.42371787 | K36: =AVERAGE(F36,H36,J36) -> 0.40460812 | M36: =SUM(M30:M35) -> 185500 | N36: =SUM(N30:N35) -> 184800 | O36: =SUM(O30:O35) -> 15400 | P36: =SUM(P30:P35) -> 0 | Q36: =SUM(Q30:Q35) -> 0 | R36: =SUM(R30:R35) -> 0 | S36: =SUM(S30:S35) -> 0 | T36: =SUM(T30:T35) -> 0 | ... Z36: =SUM(Z30:Z35) -> 0
D40: TOTALE COSTI FISSI | E40: =E36 -> 181715 | F40: =E40/$E$10 -> 0.47221231 | G40: =G36 -> 204601.29 | H40: =G40/G$10 -> 0.31789419 | I40: =I36 -> 185621.79 | J40: =I40/I$10 -> 0.42371787 | K40: =AVERAGE(F40,H40,J40) -> 0.40460812 | M40: =M36 -> 185500 | N40: =N36 -> 184800 | O40: =O36 -> 15400 | P40: =P36 -> 0 | Q40: =Q36 -> 0 | R40: =R36 -> 0 | S40: =S36 -> 0 | T40: =T36 -> 0 | ... Z40: =Z36 -> 0
D42: TOTALE COSTI | E42: =E26+E40 -> 242159.26 | F42: =E42/$E$10 -> 0.62928533 | G42: =G26+G40 -> 480844.04 | H42: =G42/G$10 -> 0.74709952 | I42: =I26+I40 -> 332298.99 | J42: =I42/I$10 -> 0.75853713 | K42: =AVERAGE(F42,H42,J42) -> 0.71164066 | M42: =M26+M40 -> 332100 | N42: =N26+N40 -> 284400 | O42: =O26+O40 -> 23700 | P42: =P26+P40 -> 0 | Q42: =Q26+Q40 -> 0 | R42: =R26+R40 -> 0 | S42: =S26+S40 -> 0 | T42: =T26+T40 -> 0 | ... Z42: =Z26+Z40 -> 0
B44: Cfix | C44: OST | D44: ONERI STRAORDINARI | E44: =IFERROR(GETPIVOTDATA(""&E$5&"",Tab_RIEP!$A$3,"M",$B44,"sM",$C44),0) -> 0 | F44: =E44/$E$10 -> 0 | G44: =IFERROR(GETPIVOTDATA(""&G$5&"",Tab_RIEP!$A$3,"M",$B44,"sM",$C44),0) -> 0 | H44: =G44/G$10 -> 0 | I44: =IFERROR(GETPIVOTDATA(""&I$5&"",Tab_RIEP!$A$3,"M",$B44,"sM",$C44),0) -> 0 | J44: =I44/I$10 -> 0 | K44: =AVERAGE(F44,H44,J44) -> 0 | M44: 1000 | N44: =SUM(O44:Z44)/$N$5*12 -> 1200 | O44: =IF(O$10>0,ROUND($M44/12,-2),0) -> 100 | P44: =IF(P$10>0,ROUND($M44/12,-2),0) -> 0 | Q44: =IF(AND(P$10>0,Q$10>0),ROUND($M44/12,-2),IF(Q$10>0,ROUND($M44/4,-2),0)) -> 0 | R44: =IF(R$10>0,ROUND($M44/12,-2),0) -> 0 | S44: =IF(S$10>0,ROUND($M44/12,-2),0) -> 0 | T44: =IF(AND(S$10>0,T$10>0),ROUND($M44/12,-2),IF(T$10>0,ROUND($M44/4,-2),0)) -> 0 | U44: =IF(U$10>0,ROUND($M44/12,-2),0) -> 0 | V44: =IF(V$10>0,ROUND($M44/12,-2),0) -> 0 | W44: =IF(AND(V$10>0,W$10>0),ROUND($M44/12,-2),IF(W$10>0,ROUND($M44/4,-2),0)) -> 0 | X44: =IF(X$10>0,ROUND($M44/12,-2),0) -> 0 | Y44: =IF(Y$10>0,ROUND($M44/12,-2),0) -> 0 | Z44: =IF(AND(Y$10>0,Z$10>0),ROUND($M44/12,-2),IF(Z$10>0,ROUND($M44/4,-2),0)) -> 0
B45: Ric | C45: ARP | D45: ALTRI RICAVI E PROVENTI | E45: =IFERROR(GETPIVOTDATA(""&E$5&"",Tab_RIEP!$A$3,"M",$B45,"sM",$C45),0) -> 4212.44 | F45: =E45/$E$10 -> 0.010946625 | G45: =IFERROR(GETPIVOTDATA(""&G$5&"",Tab_RIEP!$A$3,"M",$B45,"sM",$C45),0) -> 17294.2 | H45: =G45/G$10 -> 0.026870435 | I45: =IFERROR(GETPIVOTDATA(""&I$5&"",Tab_RIEP!$A$3,"M",$B45,"sM",$C45),0) -> 286.1 | J45: =I45/I$10 -> 0.00065307894 | K45: =AVERAGE(F45,H45,J45) -> 0.01282338 | M45: 2000 | N45: =SUM(O45:Z45)/$N$5*12 -> 2400 | O45: =IF(O$10>0,ROUND($M45/12,-2),0) -> 200 | P45: =IF(P$10>0,ROUND($M45/12,-2),0) -> 0 | Q45: =IF(AND(P$10>0,Q$10>0),ROUND($M45/12,-2),IF(Q$10>0,ROUND($M45/4,-2),0)) -> 0 | R45: =IF(R$10>0,ROUND($M45/12,-2),0) -> 0 | S45: =IF(S$10>0,ROUND($M45/12,-2),0) -> 0 | T45: =IF(AND(S$10>0,T$10>0),ROUND($M45/12,-2),IF(T$10>0,ROUND($M45/4,-2),0)) -> 0 | U45: =IF(U$10>0,ROUND($M45/12,-2),0) -> 0 | V45: =IF(V$10>0,ROUND($M45/12,-2),0) -> 0 | W45: =IF(AND(V$10>0,W$10>0),ROUND($M45/12,-2),IF(W$10>0,ROUND($M45/4,-2),0)) -> 0 | X45: =IF(X$10>0,ROUND($M45/12,-2),0) -> 0 | Y45: =IF(Y$10>0,ROUND($M45/12,-2),0) -> 0 | Z45: =IF(AND(Y$10>0,Z$10>0),ROUND($M45/12,-2),IF(Z$10>0,ROUND($M45/4,-2),0)) -> 0
B46: Ric | C46: APF | D46: ALTRI PROVENTI FINANZIARI | E46: =IFERROR(GETPIVOTDATA(""&E$5&"",Tab_RIEP!$A$3,"M",$B46,"sM",$C46),0) -> 5237.01 | F46: =E46/$E$10 -> 0.013609117 | G46: =IFERROR(GETPIVOTDATA(""&G$5&"",Tab_RIEP!$A$3,"M",$B46,"sM",$C46),0) -> 10257.55 | H46: =G46/G$10 -> 0.015937414 | I46: =IFERROR(GETPIVOTDATA(""&I$5&"",Tab_RIEP!$A$3,"M",$B46,"sM",$C46),0) -> 33951.05 | J46: =I46/I$10 -> 0.077499881 | K46: =AVERAGE(F46,H46,J46) -> 0.035682137 | M46: 3000 | N46: =SUM(O46:Z46)/$N$5*12 -> 3600 | O46: =IF(O$10>0,ROUND($M46/12,-2),0) -> 300 | P46: =IF(P$10>0,ROUND($M46/12,-2),0) -> 0 | Q46: =IF(AND(P$10>0,Q$10>0),ROUND($M46/12,-2),IF(Q$10>0,ROUND($M46/4,-2),0)) -> 0 | R46: =IF(R$10>0,ROUND($M46/12,-2),0) -> 0 | S46: =IF(S$10>0,ROUND($M46/12,-2),0) -> 0 | T46: =IF(AND(S$10>0,T$10>0),ROUND($M46/12,-2),IF(T$10>0,ROUND($M46/4,-2),0)) -> 0 | U46: =IF(U$10>0,ROUND($M46/12,-2),0) -> 0 | V46: =IF(V$10>0,ROUND($M46/12,-2),0) -> 0 | W46: =IF(AND(V$10>0,W$10>0),ROUND($M46/12,-2),IF(W$10>0,ROUND($M46/4,-2),0)) -> 0 | X46: =IF(X$10>0,ROUND($M46/12,-2),0) -> 0 | Y46: =IF(Y$10>0,ROUND($M46/12,-2),0) -> 0 | Z46: =IF(AND(Y$10>0,Z$10>0),ROUND($M46/12,-2),IF(Z$10>0,ROUND($M46/4,-2),0)) -> 0
D47: UTILE ANTE IMPOSTE | E47: =E10-E42+SUM(E44:E46) -> 152106.5 | F47: =E47/$E$10 -> 0.39527041 | G47: =G10-G42+SUM(G44:G46) -> 190322.15 | H47: =G47/G$10 -> 0.29570833 | I47: =I10-I42+SUM(I44:I46) -> 140016.9 | J47: =I47/I$10 -> 0.31961583 | K47: =AVERAGE(F47,H47,J47) -> 0.33686486 | M47: =M10-M42+SUM(M44:M46) -> 111900 | N47: =N10-N42+SUM(N44:N46) -> 45336 | O47: =O10-O42+SUM(O44:O46) -> 3778 | P47: =P10-P42+SUM(P44:P46) -> 0 | Q47: =Q10-Q42+SUM(Q44:Q46) -> 0 | R47: =R10-R42+SUM(R44:R46) -> 0 | S47: =S10-S42+SUM(S44:S46) -> 0 | T47: =T10-T42+SUM(T44:T46) -> 0 | ... Z47: =Z10-Z42+SUM(Z44:Z46) -> 0
B49: Tax | C49: IMP | D49: IMPOSTE SUL REDDITO DELL'ESERC | E49: =IFERROR(GETPIVOTDATA(""&E$5&"",Tab_RIEP!$A$3,"M",$B49,"sM",$C49),0) -> 8727.87 | F49: =E49/$E$10 -> 0.022680614 | G49: =IFERROR(GETPIVOTDATA(""&G$5&"",Tab_RIEP!$A$3,"M",$B49,"sM",$C49),0) -> 10041.03 | H49: =G49/G$10 -> 0.015601002 | I49: =IFERROR(GETPIVOTDATA(""&I$5&"",Tab_RIEP!$A$3,"M",$B49,"sM",$C49),0) -> 0 | J49: =I49/I$10 -> 0 | K49: =AVERAGE(F49,H49,J49) -> 0.012760538 | M49: =ROUND(I49,-3) -> 0
D51: UTILE NETTO | E51: =+E47-E49 -> 143378.63 | F51: =E51/$E$10 -> 0.37258979 | G51: =+G47-G49 -> 180281.12 | H51: =G51/G$10 -> 0.28010733 | I51: =+I47-I49 -> 140016.9 | J51: =I51/I$10 -> 0.31961583 | K51: =AVERAGE(F51,H51,J51) -> 0.32410432 | M51: =+M47-M49 -> 111900 | N51: =+N47-N49 -> 45336 | O51: =+O47-O49 -> 3778 | P51: =+P47-P49 -> 0 | Q51: =+Q47-Q49 -> 0 | R51: =+R47-R49 -> 0 | S51: =+S47-S49 -> 0 | T51: =+T47-T49 -> 0 | ... Z51: =+Z47-Z49 -> 0

Sheet Sigle MASTRI
B2: RIM
B3: Ric | C3: Ricavi
B4: CVar | C4: Variabili
B5: CFix | C5: Fissi
B6: Tax | C6: Imposte
B8: RCV | C8: Ricavi
B9: CAV | C9: Costi Acquisto Variabili | H9: CAV
B10: Rim_I | C10: Rimanenze INIZ | H10: Rim_I
B11: Rim_F | C11: Rimanenze FIN | H11: Rim_F
B12: CSV | C12: Costi per Servizi | H12: CSV
B13: CGT | C13: Costi Godim beni Terzi | H13: CGT
B14: CPE | C14: Costo del Personale | H14: CPE
B15: AMM | C15: Ammortamenti | H15: AMM
B16: ODG | C16: Oneri Diversi di Gestione | H16: ODG
B17: INT | C17: Interessi | H17: INT
B18: OST | C18: Oneri Straordinari | H18: OST
B19: ARP | C19: Altri Ricavi e Proventi | H19: ARP
B20: APF | C20: Altri Ricavi Finanziari | H20: APF
B21: IMP | C21: Imposte | H21: IMP
